<?xml version="1.0" ?>
<sdf version="1.4">
<world name="arm_world">
	<!-- Ground Plane -->>
	<include>
		<uri>model://ground_plane</uri>
	</include>
	<include>
		<uri>model://sun</uri>
	</include>

	<!--             -->
	<!-- ARM/GRIPPER -->
	<!--             -->
	<model name="arm">
		<plugin name="ArmPlugin" filename="libgazeboArmPlugin.so" />
		<static>false</static>

		<link name="base">
		<pose>0 0 .1 0 0 0</pose>
		<inertial>
			<pose>0 0 0 0 0 0</pose>
			<inertia>
				<ixx>0.01</ixx>
				<ixy>0</ixy>
				<ixz>0</ixz>
				<iyy>0.01</iyy>
				<iyz>0</iyz>
				<izz>0.01</izz>
			</inertia>
			<mass>10</mass>
		</inertial>
		<collision name="collision">
			<geometry>
				<box>
					<size>0.4 0.4 0.2</size>
				</box>
			</geometry>
		</collision>
		<visual name="visual">
			<geometry>
				<box>
					<size>0.4 0.4 0.2</size>
				</box>
			</geometry>
		</visual>
		</link>

		<link name="joint1">
		<pose>0 0 0.3 0 1.5707 1.5707</pose>
		<collision name="collision">
			<geometry>
				<cylinder>
					<radius>.1</radius>
					<length>.15</length>
				</cylinder>
			</geometry>
		</collision>
		<visual name="visual">
			<geometry>
				<cylinder>
					<radius>.1</radius>
					<length>.15</length>
				</cylinder>
			</geometry>
		</visual>
		</link>

		<link name="link1">
		<pose>0 0 .66 0 0 0</pose>
		<inertial>
			<mass>.25</mass>
			<inertia>
				<!-- interias are tricky to compute -->
				<ixx>0.083</ixx>
				<!-- for a box: ixx = 0.083 * mass * (y*y + z*z) -->
				<ixy>0.0</ixy>
				<!-- for a box: ixy = 0 -->
				<ixz>0.0</ixz>
				<!-- for a box: ixz = 0 -->
				<iyy>0.083</iyy>
				<!-- for a box: iyy = 0.083 * mass * (x*x + z*z) -->
				<iyz>0.0</iyz>
				<!-- for a box: iyz = 0 -->
				<izz>0.083</izz>
				<!-- for a box: izz = 0.083 * mass * (x*x + y*y) -->
			</inertia>
		</inertial>
		<collision name="collision">
			<geometry>
				<box>
					<size>.1 .1 .6</size>
				</box>
			</geometry>
		</collision>
		<visual name="visual">
			<geometry>
				<box>
					<size>.1 .1 .6</size>
				</box>
			</geometry>
		</visual>
		</link>

		<link name="joint2">
		<pose>0 0 1.01 0 1.5707 1.5707</pose>
		<collision name="collision">
			<geometry>
				<cylinder>
					<radius>.1</radius>
					<length>.15</length>
				</cylinder>
			</geometry>
		</collision>
		<visual name="visual">
			<geometry>
				<cylinder>
					<radius>.1</radius>
					<length>.15</length>
				</cylinder>
			</geometry>
		</visual>
		</link>

		<link name="link2">
		<pose>0 0 1.37 0 0 0</pose>
		<inertial>
			<mass>.2</mass>
			<inertia>
				<ixx>0.083</ixx>
				<ixy>0.0</ixy>
				<ixz>0.0</ixz>
				<iyy>0.083</iyy>
				<iyz>0.0</iyz>
				<izz>0.083</izz>
			</inertia>
		</inertial>
		<collision name="collision1">
			<geometry>
				<box>
					<size>.1 .1 .6</size>
				</box>
			</geometry>
		</collision>
		<visual name="visual1">
			<geometry>
				<box>
					<size>.1 .1 .6</size>
				</box>
			</geometry>
		</visual>
		</link>

		<link name="joint3">
		<pose>0 0 1.72 0 1.5707 1.5707</pose>
		<collision name="collision">
			<geometry>
				<cylinder>
					<radius>.1</radius>
					<length>.15</length>
				</cylinder>
			</geometry>
		</collision>
		<visual name="visual">
			<geometry>
				<cylinder>
					<radius>.1</radius>
					<length>.15</length>
				</cylinder>
			</geometry>
		</visual>
		</link>

		<link name="link3">
		<pose>0 0 2.07 0 0 0</pose>
		<inertial>
			<mass>.2</mass>
			<inertia>
				<ixx>0.083</ixx>
				<ixy>0.0</ixy>
				<ixz>0.0</ixz>
				<iyy>0.083</iyy>
				<iyz>0.0</iyz>
				<izz>0.083</izz>
			</inertia>
		</inertial>
		<collision name="collision2">
			<geometry>
				<box>
					<size>.1 .1 .6</size>
				</box>
			</geometry>
		</collision>
		<visual name="visual2">
			<geometry>
				<box>
					<size>.1 .1 .6</size>
				</box>
			</geometry>
		</visual>
		</link>
        
		<link name="gripperbase">
		    <pose>0 0 2.38 0 0 0</pose>
			<inertial>
		        <mass>0.3</mass>
		        <inertia>
		          <ixx>0.0001</ixx>
		          <ixy>0</ixy>
		          <ixz>0</ixz>
		          <iyy>0.0002</iyy>
		          <iyz>0</iyz>
		          <izz>0.0001</izz>
		        </inertia>
			</inertial>
			<visual name="gripper_link">		   
				<geometry>
		            <mesh><uri>file://meshes/gripper/gripper_base.dae</uri></mesh>
				</geometry>
			</visual>
			<collision name="gripper_link">    
				<geometry>
		            <mesh><uri>file://meshes/gripper/gripper_base.dae</uri></mesh>
				</geometry>
			</collision>
		</link>

		<link name="gripper_middle">
			<pose>0 0 2.47 0 0 0</pose>
			<collision name="middle_collision">
			<geometry>
				<box>
					<size>.01 .01 .07</size>
				</box>
			</geometry>
			</collision>              
			<visual name="middle_vision">
				<geometry>
					<box>
						<size>.01 .01 .07</size>
					</box>
				</geometry>
			</visual>
		</link>

		<link name="gripper_right">
			<pose>0 0.075 2.505 0 -1.57 -3.14</pose>
			<inertial>
				<mass>0.1</mass>
				<inertia>
                    <ixx>0.02</ixx>
                    <ixy>0</ixy>
                    <ixz>0</ixz>
                    <iyy>0.0002</iyy>
                    <iyz>0</iyz>
                    <izz>0.0002</izz>
				</inertia>
			</inertial>
			<visual name="right_gripper">
				<geometry>
					<mesh><uri>file://meshes/gripper/finger_right.dae</uri></mesh>
				</geometry>
			</visual>
			<collision name="right_gripper">
				<geometry>
                    <mesh><uri>file://meshes/gripper/finger_right.dae</uri></mesh>
			    </geometry>
			</collision>
		</link>

		<link name="gripper_left">
			<pose>0 -0.075 2.505 0 -1.57 -3.14</pose>
			<inertial>
                <mass>0.1</mass>
                <inertia>
                    <ixx>0.002</ixx>
                    <ixy>0</ixy>
                    <ixz>0</ixz>
                    <iyy>0.0002</iyy>
                    <iyz>0</iyz>
                    <izz>0.0002</izz>
                </inertia>
			</inertial>
			<visual name="left_gripper">
				<geometry>
					<mesh><uri>file://meshes/gripper/finger_left.dae</uri></mesh>
				</geometry>
			</visual>
			<collision name="left_gripper">
				<geometry>
					<mesh><uri>file://meshes/gripper/finger_left.dae</uri></mesh>
				</geometry>
			</collision>
		</link>

		<joint name="base" type="revolute">
			<pose>0 0 0 0 0 0</pose>
			<child>base</child>
			<parent>world</parent>
			<axis>
				<limit>
					<lower>-2</lower>
					<upper>2</upper>
				</limit>
				<xyz>0 0 1</xyz>
			</axis>
		</joint>

		<joint name="joint1" type="revolute">
			<pose>0 0 0 0 0 0</pose>
			<child>joint1</child>
			<parent>base</parent>
			<axis>
				<limit>
					<lower>-2</lower>
					<upper>2</upper>
				</limit>
				<xyz>0 1 0</xyz>
			</axis>
		</joint>

		<joint name="link1-join1" type="revolute">
			<pose>0 0 -0.05 0 0 0</pose>
			<child>link1</child>
			<parent>joint1</parent>
			<axis>
				<limit>
					<lower>0</lower>
					<upper>0</upper>
				</limit>
				<xyz>0 1 0</xyz>
			</axis>
		</joint>

		<joint name="joint2" type="revolute">
			<pose>0 0 -0.05 0 0 0</pose>
			<child>joint2</child>
			<parent>link1</parent>
			<axis>
				<limit>
					<lower>-2</lower>
					<upper>2</upper>
				</limit>
				<xyz>0 1 0</xyz>
			</axis>
		</joint>

		<joint name="link2-joint2" type="revolute">
			<pose>0 0 -0.05 0 0 0</pose>
			<child>link2</child>
			<parent>joint2</parent>
			<axis>
				<limit>
					<lower>0</lower>
					<upper>0</upper>
				</limit>
				<xyz>0 1 0</xyz>
			</axis>
		</joint>

		<joint name="joint3" type="revolute">
			<pose>0 0 -0.05 0 0 0</pose>
			<child>joint3</child>
			<parent>link2</parent>
			<axis>
				<limit>
					<lower>-2</lower>
					<upper>2</upper>
				</limit>
				<xyz>0 1 0</xyz>
			</axis>
		</joint>

		<joint name="link3-joint3" type="revolute">
			<pose>0 0 -0.05 0 0 0</pose>
			<child>link3</child>
			<parent>joint3</parent>
			<axis>
				<limit>
					<lower>0</lower>
					<upper>0</upper>
				</limit>
				<xyz>0 1 0</xyz>
			</axis>
		</joint>

		<joint name="gripper_right" type="prismatic">
		<pose>0 0 0 0 0 0</pose>
		<parent>gripperbase</parent>
		    <child>gripper_right</child>
		    <axis>
			<xyz>0 -1 0</xyz>
			<limit>
			    <effort>100</effort>
			    <lower>-0.01</lower>
			    <upper>0.06</upper>
			    <velocity>0.05</velocity>
			</limit>
			<dynamics>
			    <damping>0.7</damping>
			</dynamics>
		    </axis>
			</joint>

		<joint name="gripper_left" type="prismatic">
            <pose>0 0 0 0 0 0</pose>
            <parent>gripperbase</parent>
            <child>gripper_left</child>
            <axis>
                <xyz>0 1 0</xyz>
                <limit>
                    <effort>100</effort>
                    <lower>-0.01</lower>
                    <upper>0.06</upper>
                    <velocity>0.05</velocity>
                </limit>
                <dynamics>
                    <damping>0.7</damping>
                </dynamics>
            </axis>
		</joint>
		  
		<joint name="gripperbase" type="fixed">
            <pose>0 0 -0.05 0 0 0</pose>
            <parent>link3</parent>
            <child>gripperbase</child>
            <axis>
                <xyz>0 1 0</xyz>
            </axis>
		</joint>

		<joint name="gripper_middle" type="fixed">
            <pose>0 0 0 0 0 0</pose>
            <parent>gripperbase</parent>
            <child>gripper_middle</child>
 			<axis>
                <xyz>0 1 0</xyz>
            </axis>
        </joint>
		 
		<plugin name="graspPlugin" filename="libgazeboGraspPlugin.so">
      		<arm>
        		<arm_name>arm</arm_name>
        		<palm_link>gripperbase</palm_link>
        		<gripper_link>gripper_right</gripper_link>
        		<gripper_link>gripper_left</gripper_link>
      		</arm>
      		<forces_angle_tolerance>100</forces_angle_tolerance>
      		<update_rate>4</update_rate>
      		<grip_count_threshold>4</grip_count_threshold>
      		<max_grip_count>8</max_grip_count>
      		<release_tolerance>0.003</release_tolerance>
      		<disable_collisions_on_attach>false</disable_collisions_on_attach>
      		<contact_topic>__default_topic__</contact_topic>
		</plugin>		
	</model>


	<!--        -->
	<!-- CAMERA -->
	<!--        -->
	<model name="camera">
		<link name="link">
		<gravity>false</gravity>
		<!--<pose>-1.0 -3.0 0.85 0 0 1.0</pose>-->
		<!--<pose>0.75 -3.0 0.85 0 0 1.5</pose>-->
		<!--<pose>0.0 0.0 3.5 0 1.57079632679 0</pose>-->
                <pose>0.5 -3.0 0.85 0 0 1.57</pose>
		<inertial>
			<mass>0.1</mass>
		</inertial>
		<visual name="visual">
			<geometry>
				<box>
					<size>0.1 0.1 0.1</size>
				</box>
			</geometry>
		</visual>
		<sensor name="camera" type="camera">
			<camera>
				<horizontal_fov>1.047</horizontal_fov>
				<image>
					<width>1024</width>
					<height>1024</height>
				</image>
				<clip>
					<near>0.1</near>
					<far>100</far>
				</clip>
				<noise>
					<type>gaussian</type>
					<mean>0.0</mean>
					<stddev>0.007</stddev>
				</noise>
			</camera>
			<always_on>1</always_on>
			<update_rate>10</update_rate>
			<visualize>true</visualize>
		</sensor>
		</link>
	</model>

	


	<!--               -->
	<!-- BOX/COLLISION -->
	<!--               -->
	<!--<model name="box">
		<link name="link">
		<pose>0.75 0.75 0 0 0 0</pose>
		
		<collision name="box_collision">
			<geometry>
				<box>
					<size>0.10 0.10 0.10</size>
				</box>
			</geometry>
		</collision>

		<visual name="visual">
			<geometry>
				<box>
					<size>0.10 0.10 0.10</size>
				</box>
			</geometry>
			<material>
				<ambient>0.3 0.3 0.3 1</ambient>
				<diffuse>1.0 0.5 0.0 1</diffuse>
				<specular>0.01 0.01 0.01 1</specular>
				<emissive>0 0 0 1</emissive>
				<shader type='vertex'>
					<normal_map>__default__</normal_map>
				</shader>
			</material>
		</visual>

		<sensor name='my_contact' type='contact'>
			<contact>
				<collision>box_collision</collision>
			</contact>
		</sensor>
		</link>
		<plugin name="PropPlugin" filename="libgazeboPropPlugin.so" />

	</model>-->


	<!--               -->
	<!-- BALL/COLLISION -->
	<!--               -->
    <!--<model name="ball">
		<link name="link">
		<pose>0.75 0.75 0.0 0 0 0</pose>
		<collision name="ball_collision">
			<geometry>
				<sphere>
					<radius>0.05</radius>
				</sphere>
			</geometry>
		</collision>

		<visual name="visual">
			<geometry>
				<sphere>
					<radius>0.05</radius>
				</sphere>
			</geometry>
			<material>
				<ambient>0.3 0.3 0.3 1</ambient>
				<diffuse>1.0 0.5 0.0 1</diffuse>
				<specular>0.01 0.01 0.01 1</specular>
				<emissive>0 0 0 1</emissive>
				<shader type='vertex'>
					<normal_map>__default__</normal_map>
				</shader>
			</material>
		</visual>

		<sensor name='my_contact' type='contact'>
			<contact>
				<collision>ball_collision</collision>
			</contact>
		</sensor>
		</link>

		<plugin name="PropPlugin" filename="libgazeboPropPlugin.so" />
    </model>-->

	<!--               -->
	<!-- TUBE/COLLISION -->
	<!--               -->
	<model name="tube">
		<link name="link">
		<pose>1.25 0 0 0 0 0</pose>
		
		<collision name="tube_collision">
			<geometry>
			     <cylinder>
					<radius>0.05</radius>
					<length>0.1</length>
		              </cylinder>
			</geometry>
		</collision>

		<visual name="visual">
			<geometry>
				<cylinder>
					<radius>0.05</radius>
					<length>0.1</length>
		              </cylinder>
			</geometry>
			<material>
				<ambient>0.3 0.3 0.3 1</ambient>
				<diffuse>1.0 0.5 0.0 1</diffuse>
				<specular>0.01 0.01 0.01 1</specular>
				<emissive>0 0 0 1</emissive>
				<shader type='vertex'>
					<normal_map>__default__</normal_map>
				</shader>
			</material>
		</visual>

		<sensor name='my_contact' type='contact'>
			<contact>
				<collision>tube_collision</collision>
			</contact>
		</sensor>
		</link>
		<plugin name="PropPlugin" filename="libgazeboPropPlugin.so" />

	</model>-->


</world>
</sdf>
